<?xml version="1.0"?>
<robot xmlns:xacro="http://www.ros.org/wiki/xacro" name="x3_robot">

  <!-- Base Link -->
  <link name="base_link">
    <inertial>
      <mass value="1.5"/>
      <origin xyz="0 0 0"/>
      <inertia ixx="0.0347563" ixy="0" ixz="0" iyy="0.07" iyz="0" izz="0.0977"/>
    </inertial>
    <visual>
      <origin xyz="0 0 0" rpy="0 0 0"/>
      <geometry>
        <mesh filename="https://fuel.gazebosim.org/1.0/OpenRobotics/models/x3 uav/4/files/meshes/x3.dae"/>
      </geometry>
    </visual>
    <collision>
      <origin xyz="0 0 0" rpy="0 0 0"/>
      <geometry>
        <box size="0.47 0.47 0.11"/>
      </geometry>
    </collision>
  </link>

  <!-- Propeller Template -->
  <!-- You can copy-paste this block with modified joint name and position -->
  <xacro:macro name="rotor" params="name x y z mesh">
    <link name="${name}">
      <inertial>
        <mass value="0.005"/>
        <origin xyz="0 0 0"/>
        <inertia ixx="9.75e-07" ixy="0" ixz="0" iyy="4.17041e-05" iyz="0" izz="4.26041e-05"/>
      </inertial>
      <visual>
        <geometry>
          <mesh filename="${mesh}" scale="0.1 0.1 0.1"/>
        </geometry>
      </visual>
      <collision>
        <geometry>
          <cylinder radius="0.1" length="0.005"/>
        </geometry>
      </collision>
    </link>
    <joint name="X3/${name}_joint" type="revolute">
      <parent link="base_link"/>
      <child link="${name}"/>
      <origin xyz="${x} ${y} ${z}" rpy="0 0 0"/>
      <axis xyz="0 0 1"/>
      <limit lower="-1e16" upper="1e16" effort="100" velocity="100"/>
    </joint>
  </xacro:macro>

  <!-- Use the macro to define rotors -->
  <xacro:rotor name="rotor_0" x="0.13" y="-0.22" z="0.023" mesh="https://fuel.gazebosim.org/1.0/OpenRobotics/models/x3 uav/4/files/meshes/propeller_ccw.dae"/>
  <xacro:rotor name="rotor_1" x="-0.13" y="0.2" z="0.023" mesh="https://fuel.gazebosim.org/1.0/OpenRobotics/models/x3 uav/4/files/meshes/propeller_ccw.dae"/>
  <xacro:rotor name="rotor_2" x="0.13" y="0.2" z="0.023" mesh="https://fuel.gazebosim.org/1.0/OpenRobotics/models/x3 uav/4/files/meshes/propeller_cw.dae"/>
  <xacro:rotor name="rotor_3" x="-0.13" y="-0.22" z="0.023" mesh="https://fuel.gazebosim.org/1.0/OpenRobotics/models/x3 uav/4/files/meshes/propeller_cw.dae"/>

</robot>